Workbook

Sheet Rohdaten
A1: RK1: 5000H2, 100mVs, 100mA | P1: RK1, 5000H2, 100mVs, 2,3A | Y1: RK4: Holz, 100mA, 100mVs | AD1: 100mA, 2mVs | AI1: 100mA, 100mVs | AO1: RK3: Flachstahl, 5A, 100mVs | AU1: Flachstahl, hübsche Kreise, gleiche Einstellungen | AX1: Messreihe#11 | BA1: Entmagnetisierung | BC1: Messreihe#12 | BG1: Messreihe #13 HÜBSCH! | BK1: RK2: 5000Z, 100mA, 100mVs | BM1: Messreihe #14
B2: Messreihe #2 | G2: Messreihe #3 | L2: Messreihe #4 | Q2: Messreihe #5 | V2: Messreihe #6 | AA2: Messreihe #7 | AF2: Messreihe #8 | AK2: Messreihe #9 | AQ2: Messreihe #10
A4: Zeit (s) Messreihe #2 | B4: Spannung, Ch A (V) Messreihe #2 | C4: Spannung Ch B (V) Messreihe #2 | F4: Zeit (s) Messreihe #3 | G4: Spannung, Ch A (V) Messreihe #3 | H4: Spannung, Ch B (V) Messreihe #3 | K4: Zeit (s) Messreihe #4 | L4: Spannung, Ch A (V) Messreihe #4 | M4: Spannung, Ch B (V) Messreihe #4 | P4: Zeit (s) Messreihe #5 | Q4: Spannung, Ch A (V) Messreihe #5 | R4: Spannung, Ch B (V) Messreihe #5 | U4: Zeit (s) Messreihe #6 | V4: Spannung, Ch A (V) Messreihe #6 | W4: Spannung, Ch B (V) Messreihe #6 | Z4: Zeit (s) Messreihe #7 | AA4: Spannung, Ch A (V) Messreihe #7 | AB4: Spannung, Ch B (V) Messreihe #7 | AE4: Zeit (s) Messreihe #8 | AF4: Spannung, Ch A (V) Messreihe #8 | AG4: Spannung, Ch B (V) Messreihe #8 | AJ4: Zeit (s) Messreihe #9 | AK4: Spannung, Ch A (V) Messreihe #9 | AL4: Spannung, Ch B (V) Messreihe #9 | AP4: Zeit (s) Messreihe #10 | AQ4: Spannung, Ch A (V) Messreihe #10 | AR4: Spannung, Ch B (V) Messreihe #10 | AU4: Zeit (s) Messreihe #11 | AV4: Spannung, Ch A (V) Messreihe #11 | AW4: Spannung, Ch B (V) Messreihe #11 | BA4: Zeit (s) Messreihe #12 | BB4: Spannung, Ch A (V) Messreihe #12 | BC4: Spannung, Ch B (V) Messreihe #12 | BF4: Zeit (s) Messreihe #13 | BG4: Spannung, Ch A (V) Messreihe #13 | BH4: Spannung, Ch B (V) Messreihe #13 | BK4: Zeit (s) Messreihe #14 | BL4: Spannung, Ch A (V) Messreihe #14 | BM4: Spannung, Ch B (V) Messreihe #14
A5: 0 | B5: 6.687 | C5: -0.004 | F5: 0 | G5: 6.708 | H5: -0.011 | K5: 0 | L5: 6.659 | M5: -0.002 | P5: 0 | Q5: -0.463 | R5: -0.002 | U5: 0 | V5: -0.46 | W5: -0.002 | Z5: 0 | AA5: 6.749 | AB5: -0.001 | AE5: 0 | AF5: 6.725 | AG5: -0.006 | AJ5: 0 | AK5: 6.653 | AL5: -0.0007998 | AP5: 0 | AQ5: 1.008 | AR5: -0.002 | AU5: 0 | AV5: 1.003 | AW5: -0.002 | BA5: 0 | BB5: 1.004 | BC5: -0.001 | BF5: 0 | BG5: 1 | BH5: -0.01 | BK5: 0 | BL5: -6.722 | BM5: -0.002
A6: 0.05 | B6: 6.687 | C6: -0.004 | F6: 0.05 | G6: 6.708 | H6: -0.011 | K6: 0.05 | L6: 6.659 | M6: -0.0009939 | P6: 0.05 | Q6: -0.463 | R6: -0.001 | U6: 0.05 | V6: -0.46 | W6: -0.0009292 | Z6: 0.05 | AA6: 6.749 | AB6: -0.002 | AE6: 0.05 | AF6: 6.725 | AG6: -0.008 | AJ6: 0.05 | AK6: 6.652 | AL6: -0.002 | AP6: 0.05 | AQ6: 1.008 | AR6: -0.001 | AU6: 0.05 | AV6: 1.003 | AW6: -0.001 | BA6: 0.05 | BB6: 1.004 | BC6: -0.002 | BF6: 0.05 | BG6: 1 | BH6: -0.011 | BK6: 0.05 | BL6: -6.722 | BM6: -0.002
A7: 0.1 | B7: 6.686 | C7: -0.004 | F7: 0.1 | G7: 6.708 | H7: -0.011 | K7: 0.1 | L7: 6.659 | M7: -0.002 | P7: 0.1 | Q7: -0.463 | R7: -0.002 | U7: 0.1 | V7: -0.46 | W7: -0.002 | Z7: 0.1 | AA7: 6.748 | AB7: -0.001 | AE7: 0.1 | AF7: 6.725 | AG7: -0.007 | AJ7: 0.1 | AK7: 6.653 | AL7: -0.001 | AP7: 0.1 | AQ7: 1.008 | AR7: -0.002 | AU7: 0.1 | AV7: 1.003 | AW7: -0.002 | BA7: 0.1 | BB7: 1.004 | BC7: -0.001 | BF7: 0.1 | BG7: 1 | BH7: -0.011 | BK7: 0.1 | BL7: -6.722 | BM7: -0.002
A8: 0.15 | B8: 6.687 | C8: -0.004 | F8: 0.15 | G8: 6.708 | H8: -0.011 | K8: 0.15 | L8: 6.659 | M8: -0.001 | P8: 0.15 | Q8: -0.463 | R8: -0.001 | U8: 0.15 | V8: -0.46 | W8: -0.0009597 | Z8: 0.15 | AA8: 6.748 | AB8: -0.002 | AE8: 0.15 | AF8: 6.725 | AG8: -0.008 | AJ8: 0.15 | AK8: 6.652 | AL8: -0.002 | AP8: 0.15 | AQ8: 1.008 | AR8: -0.0009939 | AU8: 0.15 | AV8: 1.003 | AW8: -0.001 | BA8: 0.15 | BB8: 1.004 | BC8: -0.002 | BF8: 0.15 | BG8: 1 | BH8: -0.011 | BK8: 0.15 | BL8: -6.723 | BM8: -0.002
A9: 0.2 | B9: 6.686 | C9: -0.004 | F9: 0.2 | G9: 6.708 | H9: -0.011 | K9: 0.2 | L9: 6.659 | M9: -0.002 | P9: 0.2 | Q9: -0.463 | R9: -0.002 | U9: 0.2 | V9: -0.46 | W9: -0.002 | Z9: 0.2 | AA9: 6.748 | AB9: -0.001 | AE9: 0.2 | AF9: 6.725 | AG9: -0.007 | AJ9: 0.2 | AK9: 6.652 | AL9: -0.0008547 | AP9: 0.2 | AQ9: 1.008 | AR9: -0.002 | AU9: 0.2 | AV9: 1.003 | AW9: -0.002 | BA9: 0.2 | BB9: 1.004 | BC9: -0.001 | BF9: 0.2 | BG9: 1 | BH9: -0.011 | BK9: 0.2 | BL9: -6.722 | BM9: -0.002
A10: 0.25 | B10: 6.687 | C10: -0.004 | F10: 0.25 | G10: 6.708 | H10: -0.011 | K10: 0.25 | L10: 6.659 | M10: -0.0009951 | P10: 0.25 | Q10: -0.463 | R10: -0.001 | U10: 0.25 | V10: -0.46 | W10: -0.0009048 | Z10: 0.25 | AA10: 6.748 | AB10: -0.002 | AE10: 0.25 | AF10: 6.722 | AG10: -0.008 | AJ10: 0.25 | AK10: 6.652 | AL10: -0.002 | AP10: 0.25 | AQ10: 1.007 | AR10: -0.001 | AU10: 0.25 | AV10: 1.003 | AW10: -0.001 | BA10: 0.25 | BB10: 1.004 | BC10: -0.002 | BF10: 0.25 | BG10: 1 | BH10: -0.011 | BK10: 0.25 | BL10: -6.723 | BM10: -0.002
A11: 0.3 | B11: 6.686 | C11: -0.005 | F11: 0.3 | G11: 6.708 | H11: -0.011 | K11: 0.3 | L11: 6.659 | M11: -0.002 | P11: 0.3 | Q11: -0.463 | R11: -0.002 | U11: 0.3 | V11: -0.46 | W11: -0.002 | Z11: 0.3 | AA11: 6.748 | AB11: -0.001 | AE11: 0.3 | AF11: 6.701 | AG11: -0.007 | AJ11: 0.3 | AK11: 6.652 | AL11: -0.001 | AP11: 0.3 | AQ11: 1.008 | AR11: -0.002 | AU11: 0.3 | AV11: 1.003 | AW11: -0.002 | BA11: 0.3 | BB11: 1.004 | BC11: -0.001 | BF11: 0.3 | BG11: 1 | BH11: -0.011 | BK11: 0.3 | BL11: -6.722 | BM11: -0.002
A12: 0.35 | B12: 6.687 | C12: -0.003 | F12: 0.35 | G12: 6.708 | H12: -0.011 | K12: 0.35 | L12: 6.659 | M12: -0.000917 | P12: 0.35 | Q12: -0.463 | R12: -0.001 | U12: 0.35 | V12: -0.46 | W12: -0.0009438 | Z12: 0.35 | AA12: 6.748 | AB12: -0.002 | AE12: 0.35 | AF12: 6.665 | AG12: -0.008 | AJ12: 0.35 | AK12: 6.652 | AL12: -0.002 | AP12: 0.35 | AQ12: 1.008 | AR12: -0.001 | AU12: 0.35 | AV12: 1.003 | AW12: -0.001 | BA12: 0.35 | BB12: 1.004 | BC12: -0.002 | BF12: 0.35 | BG12: 1 | BH12: -0.011 | BK12: 0.35 | BL12: -6.723 | BM12: -0.002
A13: 0.4 | B13: 6.686 | C13: -0.004 | F13: 0.4 | G13: 6.708 | H13: -0.011 | K13: 0.4 | L13: 6.659 | M13: -0.002 | P13: 0.4 | Q13: -0.463 | R13: -0.002 | U13: 0.4 | V13: -0.46 | W13: -0.002 | Z13: 0.4 | AA13: 6.747 | AB13: -0.001 | AE13: 0.4 | AF13: 6.641 | AG13: -0.007 | AJ13: 0.4 | AK13: 6.652 | AL13: -0.0008328 | AP13: 0.4 | AQ13: 1.008 | AR13: -0.002 | AU13: 0.4 | AV13: 1.003 | AW13: -0.002 | BA13: 0.4 | BB13: 1.004 | BC13: -0.001 | BF13: 0.4 | BG13: 1 | BH13: -0.011 | BK13: 0.4 | BL13: -6.722 | BM13: -0.002
A14: 0.45 | B14: 6.687 | C14: -0.004 | F14: 0.45 | G14: 6.708 | H14: -0.011 | K14: 0.45 | L14: 6.659 | M14: -0.0009731 | P14: 0.45 | Q14: -0.463 | R14: -0.001 | U14: 0.45 | V14: -0.46 | W14: -0.0006802 | Z14: 0.45 | AA14: 6.728 | AB14: -0.002 | AE14: 0.45 | AF14: 6.621 | AG14: -0.008 | AJ14: 0.45 | AK14: 6.651 | AL14: -0.001 | AP14: 0.45 | AQ14: 1.008 | AR14: -0.001 | AU14: 0.45 | AV14: 1.003 | AW14: -0.001 | BA14: 0.45 | BB14: 1.004 | BC14: -0.002 | BF14: 0.45 | BG14: 1 | BH14: -0.011 | BK14: 0.45 | BL14: -6.723 | BM14: -0.002
A15: 0.5 | B15: 6.686 | C15: -0.004 | F15: 0.5 | G15: 6.708 | H15: -0.011 | K15: 0.5 | L15: 6.659 | M15: -0.002 | P15: 0.5 | Q15: -0.463 | R15: -0.002 | U15: 0.5 | V15: -0.46 | W15: -0.002 | Z15: 0.5 | AA15: 6.688 | AB15: -0.001 | AE15: 0.5 | AF15: 6.608 | AG15: -0.007 | AJ15: 0.5 | AK15: 6.643 | AL15: -0.001 | AP15: 0.5 | AQ15: 1.008 | AR15: -0.002 | AU15: 0.5 | AV15: 1.003 | AW15: -0.002 | BA15: 0.5 | BB15: 1.003 | BC15: -0.0009951 | BF15: 0.5 | BG15: 1 | BH15: -0.011 | BK15: 0.5 | BL15: -6.722 | BM15: -0.002
A16: 0.55 | B16: 6.687 | C16: -0.004 | F16: 0.55 | G16: 6.708 | H16: -0.011 | K16: 0.55 | L16: 6.66 | M16: -0.0009243 | P16: 0.55 | Q16: -0.462 | R16: -0.001 | U16: 0.55 | V16: -0.46 | W16: -0.001 | Z16: 0.55 | AA16: 6.65 | AB16: -0.002 | AE16: 0.55 | AF16: 6.59 | AG16: -0.008 | AJ16: 0.55 | AK16: 6.628 | AL16: -0.002 | AP16: 0.55 | AQ16: 1.008 | AR16: -0.001 | AU16: 0.55 | AV16: 1.003 | AW16: -0.001 | BA16: 0.55 | BB16: 0.998 | BC16: -0.002 | BF16: 0.55 | BG16: 1 | BH16: -0.011 | BK16: 0.55 | BL16: -6.717 | BM16: -0.002
... A1354: 67.45 | B1354: -0.234 | C1354: -0.306 | F1354: 67.45 | G1354: -6.391 | H1354: -0.994 | K1354: 67.45 | L1354: -5.747 | M1354: -0.976 | P1354: 67.45 | Q1354: 0.24 | R1354: 1.253 | U1354: 67.45 | V1354: 0.101 | W1354: 1.215 | Z1354: 67.45 | AA1354: -1.751 | AB1354: -0.003 | AE1354: 67.45 | AF1354: 2.928 | AG1354: -0.057 | AJ1354: 67.45 | AK1354: 6.865 | AL1354: -0.002 | AP1354: 67.45 | AQ1354: -0.771 | AR1354: -0.93 | AU1354: 67.45 | AV1354: -0.524 | AW1354: -0.892 | BA1354: 67.45 | BB1354: -0.831 | BC1354: -0.94 | BF1354: 67.45 | BG1354: -0.991 | BH1354: -0.958 | BK1354: 67.45 | BL1354: -3.534 | BM1354: -0.003
A1355: 67.5 | B1355: -0.237 | C1355: -0.312 | F1355: 67.5 | G1355: -6.433 | H1355: -0.995 | K1355: 67.5 | L1355: -5.748 | M1355: -0.977 | P1355: 67.5 | Q1355: 0.241 | R1355: 1.252 | U1355: 67.5 | V1355: 0.102 | W1355: 1.217 | Z1355: 67.5 | AA1355: -1.733 | AB1355: -0.004 | AE1355: 67.5 | AF1355: 2.96 | AG1355: -0.058 | AP1355: 67.5 | AQ1355: -0.774 | AR1355: -0.931 | AU1355: 67.5 | AV1355: -0.526 | AW1355: -0.892 | BA1355: 67.5 | BB1355: -0.826 | BC1355: -0.939 | BF1355: 67.5 | BG1355: -0.991 | BH1355: -0.957 | BK1355: 67.5 | BL1355: -3.574 | BM1355: -0.002
A1356: 67.55 | B1356: -0.239 | C1356: -0.317 | F1356: 67.55 | G1356: -6.476 | H1356: -0.995 | K1356: 67.55 | L1356: -5.748 | M1356: -0.976 | P1356: 67.55 | Q1356: 0.242 | R1356: 1.253 | U1356: 67.55 | V1356: 0.103 | W1356: 1.216 | Z1356: 67.55 | AA1356: -1.707 | AB1356: -0.003 | AE1356: 67.55 | AF1356: 2.983 | AG1356: -0.057 | AP1356: 67.55 | AQ1356: -0.774 | AR1356: -0.93 | AU1356: 67.55 | AV1356: -0.527 | AW1356: -0.892 | BA1356: 67.55 | BB1356: -0.82 | BC1356: -0.939 | BF1356: 67.55 | BG1356: -0.991 | BH1356: -0.959 | BK1356: 67.55 | BL1356: -3.61 | BM1356: -0.003
A1357: 67.6 | B1357: -0.242 | C1357: -0.323 | F1357: 67.6 | G1357: -6.502 | H1357: -0.996 | K1357: 67.6 | L1357: -5.743 | M1357: -0.977 | P1357: 67.6 | Q1357: 0.244 | R1357: 1.252 | U1357: 67.6 | V1357: 0.104 | W1357: 1.218 | Z1357: 67.6 | AA1357: -1.675 | AB1357: -0.004 | AE1357: 67.6 | AF1357: 2.997 | AG1357: -0.058 | AP1357: 67.6 | AQ1357: -0.775 | AR1357: -0.93 | AU1357: 67.6 | AV1357: -0.528 | AW1357: -0.892 | BA1357: 67.6 | BB1357: -0.815 | BC1357: -0.938 | BF1357: 67.6 | BG1357: -0.991 | BH1357: -0.957 | BK1357: 67.6 | BL1357: -3.638 | BM1357: -0.002
A1358: 67.65 | B1358: -0.245 | C1358: -0.33 | F1358: 67.65 | G1358: -6.515 | H1358: -0.995 | K1358: 67.65 | L1358: -5.738 | M1358: -0.976 | P1358: 67.65 | Q1358: 0.245 | R1358: 1.254 | U1358: 67.65 | V1358: 0.105 | W1358: 1.217 | Z1358: 67.65 | AA1358: -1.642 | AB1358: -0.003 | AE1358: 67.65 | AF1358: 3.011 | AG1358: -0.057 | AP1358: 67.65 | AQ1358: -0.776 | AR1358: -0.93 | AU1358: 67.65 | AV1358: -0.528 | AW1358: -0.893 | BA1358: 67.65 | BB1358: -0.811 | BC1358: -0.939 | BF1358: 67.65 | BG1358: -0.991 | BH1358: -0.959 | BK1358: 67.65 | BL1358: -3.66 | BM1358: -0.003
A1359: 67.7 | B1359: -0.248 | C1359: -0.34 | F1359: 67.7 | G1359: -6.529 | H1359: -0.996 | K1359: 67.7 | L1359: -5.739 | M1359: -0.977 | P1359: 67.7 | Q1359: 0.246 | R1359: 1.252 | U1359: 67.7 | V1359: 0.106 | W1359: 1.218 | Z1359: 67.7 | AA1359: -1.614 | AB1359: -0.004 | AE1359: 67.7 | AF1359: 3.03 | AG1359: -0.058 | AP1359: 67.7 | AQ1359: -0.777 | AR1359: -0.93 | AU1359: 67.7 | AV1359: -0.529 | AW1359: -0.892 | BA1359: 67.7 | BB1359: -0.808 | BC1359: -0.938 | BF1359: 67.7 | BG1359: -0.991 | BH1359: -0.957 | BK1359: 67.7 | BL1359: -3.679 | BM1359: -0.002
A1360: 67.75 | B1360: -0.25 | C1360: -0.348 | F1360: 67.75 | G1360: -6.541 | H1360: -0.996 | K1360: 67.75 | L1360: -5.741 | M1360: -0.976 | P1360: 67.75 | Q1360: 0.246 | R1360: 1.254 | U1360: 67.75 | V1360: 0.107 | W1360: 1.218 | Z1360: 67.75 | AA1360: -1.592 | AB1360: -0.003 | AE1360: 67.75 | AF1360: 3.066 | AG1360: -0.057 | AP1360: 67.75 | AQ1360: -0.779 | AR1360: -0.93 | AU1360: 67.75 | AV1360: -0.529 | AW1360: -0.893 | BA1360: 67.75 | BB1360: -0.804 | BC1360: -0.938 | BF1360: 67.75 | BG1360: -0.991 | BH1360: -0.958 | BK1360: 67.75 | BL1360: -3.697 | BM1360: -0.003
A1361: 67.8 | B1361: -0.253 | C1361: -0.359 | F1361: 67.8 | G1361: -6.554 | H1361: -0.997 | K1361: 67.8 | L1361: -5.744 | M1361: -0.977 | P1361: 67.8 | Q1361: 0.247 | R1361: 1.253 | U1361: 67.8 | V1361: 0.108 | W1361: 1.219 | Z1361: 67.8 | AA1361: -1.566 | AB1361: -0.004 | AE1361: 67.8 | AF1361: 3.116 | AG1361: -0.057 | AP1361: 67.8 | AQ1361: -0.78 | AR1361: -0.931 | AU1361: 67.8 | AV1361: -0.529 | AW1361: -0.892 | BA1361: 67.8 | BB1361: -0.801 | BC1361: -0.937 | BF1361: 67.8 | BG1361: -0.991 | BH1361: -0.958 | BK1361: 67.8 | BL1361: -3.715 | BM1361: -0.003
A1362: 67.85 | B1362: -0.255 | C1362: -0.369 | F1362: 67.85 | G1362: -6.571 | H1362: -0.996 | K1362: 67.85 | L1362: -5.747 | M1362: -0.976 | P1362: 67.85 | Q1362: 0.248 | R1362: 1.254 | U1362: 67.85 | V1362: 0.11 | W1362: 1.219 | Z1362: 67.85 | AA1362: -1.539 | AB1362: -0.003 | AE1362: 67.85 | AF1362: 3.154 | AG1362: -0.057 | AP1362: 67.85 | AQ1362: -0.78 | AR1362: -0.931 | AU1362: 67.85 | AV1362: -0.529 | AW1362: -0.893 | BA1362: 67.85 | BB1362: -0.799 | BC1362: -0.938 | BF1362: 67.85 | BG1362: -0.991 | BH1362: -0.959 | BK1362: 67.85 | BL1362: -3.737 | BM1362: -0.003
A1363: 67.9 | B1363: -0.258 | C1363: -0.382 | F1363: 67.9 | G1363: -6.595 | H1363: -0.997 | K1363: 67.9 | L1363: -5.748 | M1363: -0.977 | P1363: 67.9 | Q1363: 0.25 | R1363: 1.253 | U1363: 67.9 | V1363: 0.111 | W1363: 1.221 | Z1363: 67.9 | AA1363: -1.506 | AB1363: -0.005 | AE1363: 67.9 | AF1363: 3.18 | AG1363: -0.057 | AP1363: 67.9 | AQ1363: -0.78 | AR1363: -0.931 | AU1363: 67.9 | AV1363: -0.529 | AW1363: -0.893 | BA1363: 67.9 | BB1363: -0.797 | BC1363: -0.937 | BF1363: 67.9 | BG1363: -0.991 | BH1363: -0.958 | BK1363: 67.9 | BL1363: -3.753 | BM1363: -0.003
A1364: 67.95 | B1364: -0.262 | C1364: -0.395 | F1364: 67.95 | G1364: -6.623 | H1364: -0.996 | K1364: 67.95 | L1364: -5.749 | M1364: -0.976 | P1364: 67.95 | Q1364: 0.25 | R1364: 1.254 | U1364: 67.95 | V1364: 0.112 | W1364: 1.22 | Z1364: 67.95 | AA1364: -1.469 | AB1364: -0.003 | AE1364: 67.95 | AF1364: 3.193 | AG1364: -0.056 | AP1364: 67.95 | AQ1364: -0.783 | AR1364: -0.931 | AU1364: 67.95 | AV1364: -0.529 | AW1364: -0.893 | BA1364: 67.95 | BB1364: -0.794 | BC1364: -0.938 | BF1364: 67.95 | BG1364: -0.991 | BH1364: -0.958 | BK1364: 67.95 | BL1364: -3.769 | BM1364: -0.003
A1365: 68 | B1365: -0.265 | C1365: -0.41 | F1365: 68 | G1365: -6.649 | H1365: -0.998 | K1365: 68 | L1365: -5.75 | M1365: -0.977 | P1365: 68 | Q1365: 0.251 | R1365: 1.253 | U1365: 68 | V1365: 0.114 | W1365: 1.222 | Z1365: 68 | AA1365: -1.425 | AB1365: -0.004 | AE1365: 68 | AF1365: 3.203 | AG1365: -0.057 | AP1365: 68 | AQ1365: -0.784 | AR1365: -0.931 | AU1365: 68 | AV1365: -0.529 | AW1365: -0.892 | BA1365: 68 | BB1365: -0.788 | BC1365: -0.936 | BF1365: 68 | BG1365: -0.991 | BH1365: -0.957 | BK1365: 68 | BL1365: -3.779 | BM1365: -0.003
A1366: 68.05 | B1366: -0.269 | C1366: -0.425 | F1366: 68.05 | G1366: -6.668 | H1366: -0.997 | K1366: 68.05 | L1366: -5.75 | M1366: -0.976 | P1366: 68.05 | Q1366: 0.252 | R1366: 1.254 | U1366: 68.05 | V1366: 0.115 | W1366: 1.221 | Z1366: 68.05 | AA1366: -1.382 | AB1366: -0.003 | AE1366: 68.05 | AF1366: 3.214 | AG1366: -0.057 | AP1366: 68.05 | AQ1366: -0.785 | AR1366: -0.931 | AU1366: 68.05 | AV1366: -0.529 | AW1366: -0.893 | BA1366: 68.05 | BB1366: -0.779 | BC1366: -0.936 | BF1366: 68.05 | BG1366: -0.991 | BH1366: -0.958 | BK1366: 68.05 | BL1366: -3.795 | BM1366: -0.003
... A1501: 74.8 | B1501: -0.708 | C1501: -0.743 | F1501: 74.8 | G1501: -5.803 | H1501: -0.992 | K1501: 74.8 | L1501: -6.617 | M1501: -0.987 | P1501: 74.8 | Q1501: 0.38 | R1501: 1.258 | U1501: 74.8 | V1501: 0.229 | W1501: 1.251 | Z1501: 74.8 | AA1501: -0.058 | AB1501: -0.004 | AE1501: 74.8 | AF1501: 5.301 | AG1501: -0.053 | AP1501: 74.8 | AQ1501: -0.915 | AR1501: -0.943 | AU1501: 74.8 | AV1501: -0.672 | AW1501: -0.917 | BA1501: 74.8 | BB1501: -0.353 | BC1501: -0.875 | BF1501: 74.8 | BG1501: -0.841 | BH1501: -0.949 | BK1501: 74.8 | BL1501: -6.827 | BM1501: -0.005
A1502: 74.85 | B1502: -0.713 | C1502: -0.743 | F1502: 74.85 | G1502: -5.787 | H1502: -0.991 | K1502: 74.85 | L1502: -6.617 | M1502: -0.986 | P1502: 74.85 | Q1502: 0.381 | R1502: 1.259 | U1502: 74.85 | V1502: 0.229 | W1502: 1.25 | Z1502: 74.85 | AA1502: -0.058 | AB1502: -0.003 | AE1502: 74.85 | AF1502: 5.311 | AG1502: -0.053 | AP1502: 74.85 | AQ1502: -0.916 | AR1502: -0.943 | AU1502: 74.85 | AV1502: -0.674 | AW1502: -0.918 | BA1502: 74.85 | BB1502: -0.35 | BC1502: -0.875 | BF1502: 74.85 | BG1502: -0.841 | BH1502: -0.95
A1503: 74.9 | B1503: -0.719 | C1503: -0.746 | F1503: 74.9 | G1503: -5.778 | H1503: -0.992 | K1503: 74.9 | L1503: -6.617 | M1503: -0.987 | P1503: 74.9 | Q1503: 0.382 | R1503: 1.258 | U1503: 74.9 | V1503: 0.231 | W1503: 1.251 | Z1503: 74.9 | AA1503: -0.058 | AB1503: -0.004 | AE1503: 74.9 | AF1503: 5.323 | AG1503: -0.054 | AP1503: 74.9 | AQ1503: -0.918 | AR1503: -0.944 | AU1503: 74.9 | AV1503: -0.677 | AW1503: -0.918 | BA1503: 74.9 | BB1503: -0.346 | BC1503: -0.873 | BF1503: 74.9 | BG1503: -0.84 | BH1503: -0.949
A1504: 74.95 | B1504: -0.73 | C1504: -0.747 | F1504: 74.95 | G1504: -5.773 | H1504: -0.99 | K1504: 74.95 | L1504: -6.617 | M1504: -0.986 | P1504: 74.95 | Q1504: 0.383 | R1504: 1.259 | U1504: 74.95 | V1504: 0.233 | W1504: 1.251 | Z1504: 74.95 | AA1504: -0.058 | AB1504: -0.003 | AE1504: 74.95 | AF1504: 5.329 | AG1504: -0.053 | AP1504: 74.95 | AQ1504: -0.92 | AR1504: -0.944 | AU1504: 74.95 | AV1504: -0.678 | AW1504: -0.918 | BA1504: 74.95 | BB1504: -0.341 | BC1504: -0.873 | BF1504: 74.95 | BG1504: -0.836 | BH1504: -0.949
A1505: 75 | B1505: -0.742 | C1505: -0.75 | F1505: 75 | G1505: -5.764 | H1505: -0.992 | K1505: 75 | L1505: -6.617 | M1505: -0.987 | P1505: 75 | Q1505: 0.383 | R1505: 1.258 | U1505: 75 | V1505: 0.234 | W1505: 1.251 | Z1505: 75 | AA1505: -0.058 | AB1505: -0.005 | AE1505: 75 | AF1505: 5.333 | AG1505: -0.054 | AP1505: 75 | AQ1505: -0.921 | AR1505: -0.944 | AU1505: 75 | AV1505: -0.678 | AW1505: -0.918 | BA1505: 75 | BB1505: -0.334 | BC1505: -0.87 | BF1505: 75 | BG1505: -0.834 | BH1505: -0.948
A1506: 75.05 | B1506: -0.755 | C1506: -0.752 | F1506: 75.05 | G1506: -5.757 | H1506: -0.991 | K1506: 75.05 | L1506: -6.617 | M1506: -0.986 | P1506: 75.05 | Q1506: 0.384 | R1506: 1.259 | U1506: 75.05 | V1506: 0.236 | W1506: 1.251 | Z1506: 75.05 | AA1506: -0.058 | AB1506: -0.003 | AE1506: 75.05 | AF1506: 5.334 | AG1506: -0.053 | AP1506: 75.05 | AQ1506: -0.922 | AR1506: -0.944 | AU1506: 75.05 | AV1506: -0.679 | AW1506: -0.919 | BA1506: 75.05 | BB1506: -0.33 | BC1506: -0.87 | BF1506: 75.05 | BG1506: -0.83 | BH1506: -0.949
A1507: 75.1 | B1507: -0.769 | C1507: -0.756 | F1507: 75.1 | G1507: -5.753 | H1507: -0.991 | K1507: 75.1 | L1507: -6.617 | M1507: -0.987 | P1507: 75.1 | Q1507: 0.386 | R1507: 1.259 | U1507: 75.1 | V1507: 0.237 | W1507: 1.251 | Z1507: 75.1 | AA1507: -0.058 | AB1507: -0.004 | AE1507: 75.1 | AF1507: 5.338 | AG1507: -0.054 | AP1507: 75.1 | AQ1507: -0.924 | AR1507: -0.944 | AU1507: 75.1 | AV1507: -0.68 | AW1507: -0.918 | BA1507: 75.1 | BB1507: -0.325 | BC1507: -0.867 | BF1507: 75.1 | BG1507: -0.827 | BH1507: -0.948
A1508: 75.15 | B1508: -0.781 | C1508: -0.757 | F1508: 75.15 | G1508: -5.752 | H1508: -0.99 | K1508: 75.15 | L1508: -6.617 | M1508: -0.986 | P1508: 75.15 | Q1508: 0.387 | R1508: 1.259 | U1508: 75.15 | V1508: 0.239 | W1508: 1.252 | Z1508: 75.15 | AA1508: -0.058 | AB1508: -0.003 | AE1508: 75.15 | AF1508: 5.345 | AG1508: -0.053 | AP1508: 75.15 | AQ1508: -0.925 | AR1508: -0.944 | AU1508: 75.15 | AV1508: -0.681 | AW1508: -0.919 | BA1508: 75.15 | BB1508: -0.323 | BC1508: -0.867 | BF1508: 75.15 | BG1508: -0.824 | BH1508: -0.949
A1509: 75.2 | B1509: -0.788 | C1509: -0.76 | F1509: 75.2 | G1509: -5.751 | H1509: -0.991 | K1509: 75.2 | L1509: -6.618 | M1509: -0.987 | P1509: 75.2 | Q1509: 0.389 | R1509: 1.259 | U1509: 75.2 | V1509: 0.24 | W1509: 1.252 | Z1509: 75.2 | AA1509: -0.058 | AB1509: -0.004 | AE1509: 75.2 | AF1509: 5.356 | AG1509: -0.053 | AP1509: 75.2 | AQ1509: -0.927 | AR1509: -0.944 | AU1509: 75.2 | AV1509: -0.683 | AW1509: -0.919 | BA1509: 75.2 | BB1509: -0.319 | BC1509: -0.865 | BF1509: 75.2 | BG1509: -0.822 | BH1509: -0.947
A1510: 75.25 | B1510: -0.793 | C1510: -0.76 | F1510: 75.25 | G1510: -5.744 | H1510: -0.99 | K1510: 75.25 | L1510: -6.617 | M1510: -0.986 | P1510: 75.25 | Q1510: 0.391 | R1510: 1.259 | U1510: 75.25 | V1510: 0.24 | W1510: 1.252 | Z1510: 75.25 | AA1510: -0.058 | AB1510: -0.003 | AE1510: 75.25 | AF1510: 5.364 | AG1510: -0.053 | AP1510: 75.25 | AQ1510: -0.928 | AR1510: -0.944 | AU1510: 75.25 | AV1510: -0.685 | AW1510: -0.919 | BA1510: 75.25 | BB1510: -0.314 | BC1510: -0.864 | BF1510: 75.25 | BG1510: -0.819 | BH1510: -0.949
A1511: 75.3 | B1511: -0.801 | C1511: -0.762 | F1511: 75.3 | G1511: -5.735 | H1511: -0.991 | K1511: 75.3 | L1511: -6.618 | M1511: -0.987 | P1511: 75.3 | Q1511: 0.393 | R1511: 1.259 | U1511: 75.3 | V1511: 0.241 | W1511: 1.252 | Z1511: 75.3 | AA1511: -0.058 | AB1511: -0.004 | AE1511: 75.3 | AF1511: 5.372 | AG1511: -0.053 | AP1511: 75.3 | AQ1511: -0.93 | AR1511: -0.944 | AU1511: 75.3 | AV1511: -0.686 | AW1511: -0.919 | BA1511: 75.3 | BB1511: -0.307 | BC1511: -0.861 | BF1511: 75.3 | BG1511: -0.815 | BH1511: -0.947
A1512: 75.35 | B1512: -0.811 | C1512: -0.763 | F1512: 75.35 | G1512: -5.721 | H1512: -0.99 | K1512: 75.35 | L1512: -6.617 | M1512: -0.986 | P1512: 75.35 | Q1512: 0.395 | R1512: 1.259 | U1512: 75.35 | V1512: 0.242 | W1512: 1.252 | Z1512: 75.35 | AA1512: -0.058 | AB1512: -0.003 | AE1512: 75.35 | AF1512: 5.381 | AG1512: -0.053 | AP1512: 75.35 | AQ1512: -0.931 | AR1512: -0.945 | AU1512: 75.35 | AV1512: -0.688 | AW1512: -0.92 | BA1512: 75.35 | BB1512: -0.302 | BC1512: -0.861 | BF1512: 75.35 | BG1512: -0.813 | BH1512: -0.948
...

Sheet Auswerteparameter
A1: Sättigungsspannung Anfang Messreihe #4 | B1: Ende #4 | C1: Spannungsdifferenz #4 | D1: Gesamtzeit #4 | F1: Anfang #5 | G1: Ende#5 | H1: Diff. #5 | I1: Zeit #5 | K1: Anfang #6 | L1: Ende #6 | M1: Diff. #6 | N1: Zeit #6 | P1: Anfang #7 | Q1: Ende #7 | R1: Diff. #7 | S1: Zeit #7 | U1: Anfang #8 | V1: Ende #8 | W1: Diff. #8 | X1: Zeit #8 | Z1: Anfang #9 | AA1: Ende #9 | AB1: Diff. #9 | AC1: Zeit #9 | AE1: Anfang #10 | AF1: Ende #10 | AG1: Diff. #10 | AH1: Zeit #10 | AJ1: Anfang #11 | AK1: Ende #11 | AL1: Diff. #11 | AM1: Zeit #11 | AO1: Anfang #13 | AP1: Ende #13 | AQ1: Diff. #13 | AR1: Zeit #13 | AT1: Anfang #14 | AU1: Ende #14 | AV1: Diff. #14 | AW1: Zeit #14
A2: =Rohdaten!M5 -> -0.002 | B2: =Rohdaten!M3505 -> -0.004 | C2: =A2-B2 -> 0.002 | D2: =Rohdaten!K3505 -> 175 | F2: =Rohdaten!R5 -> -0.002 | G2: =Rohdaten!R3697 -> -0.007 | H2: =F2-G2 -> 0.005 | I2: =Rohdaten!P3697 -> 184.6 | K2: =Rohdaten!W5 -> -0.002 | L2: =Rohdaten!W4225 -> -0.008 | M2: =K2-L2 -> 0.006 | N2: =Rohdaten!U4225 -> 211 | P2: =Rohdaten!AB5 -> -0.001 | Q2: =Rohdaten!AB1915 -> -0.003 | R2: =P2-Q2 -> 0.002 | S2: =Rohdaten!Z1915 -> 95.5 | U2: =Rohdaten!AG5 -> -0.006 | V2: =Rohdaten!AG1653 -> -0.052 | W2: =U2-V2 -> 0.046 | X2: =Rohdaten!AE1653 -> 82.4 | Z2: =Rohdaten!AL5 -> -0.0007998 | AA2: =Rohdaten!AL1354 -> -0.002 | AB2: =Z2-AA2 -> 0.0012002 | AC2: =Rohdaten!AJ1354 -> 67.45 | AE2: =Rohdaten!AR5 -> -0.002 | AF2: =Rohdaten!AR3375 -> -0.005 | AG2: =AE2-AF2 -> 0.003 | AH2: =Rohdaten!AP3375 -> 168.5 | AJ2: =Rohdaten!AW5 -> -0.002 | AK2: =Rohdaten!AW7054 -> -0.008 | AL2: =AJ2-AK2 -> 0.006 | AM2: =Rohdaten!AU7054 -> 352.45 | AO2: =Rohdaten!BH5 -> -0.01 | AP2: =Rohdaten!BH8019 -> -0.492 | AQ2: =AO2-AP2 -> 0.482 | AR2: =Rohdaten!BF8019 -> 400.7 | AT2: =Rohdaten!BM5 -> -0.002 | AU2: =Rohdaten!BM1501 -> -0.005 | AV2: =AT2-AU2 -> 0.003 | AW2: =Rohdaten!BK1501 -> 74.8
A4: Step #4 | F4: Step #5 | K4: Step #6 | P4: Step #7 | U4: Step #8 | Z4: Step #9 | AE4: Step #10 | AJ4: Step #11 | AO4: Step #13 | AT4: Step #14
A5: =C2/D2 -> 1.1428571e-05 | F5: =H2/I2 -> 2.708559e-05 | K5: =M2/N2 -> 2.8436019e-05 | P5: =R2/S2 -> 2.0942408e-05 | U5: =W2/X2 -> 0.00055825243 | Z5: =AB2/AC2 -> 1.7793921e-05 | AE5: =AG2/AH2 -> 1.7804154e-05 | AJ5: =AL2/AM2 -> 1.7023691e-05 | AO5: =AQ2/AR2 -> 0.0012028949 | AT5: =AV2/AW2 -> 4.0106952e-05

Sheet Auswertedaten
C1: #4 | E1: #5 | G1: #6 | I1: #7 | K1: #8 | M1: #9 | O1: #10 | Q1: #11 | S1: #13 | U1: #14
C2: Fluss | E2: Fluss | G2: Fluss | I2: Fluss | K2: Fluss | M2: Fluss | O2: Fluss | Q2: Fluss | S2: Fluss | U2: Fluss
C3: =(Auswerteparameter!A$5*Rohdaten!K5*Rohdaten!M5) -> 0 | G3: =(Auswerteparameter!K$5*Rohdaten!U5*Rohdaten!W5) -> 0 | I3: =(Rohdaten!Z5*Rohdaten!AB5*Auswerteparameter!P$5) -> 0 | K3: =(Auswerteparameter!U$5*Rohdaten!AE5*Rohdaten!AG5) -> 0 | M3: =(Auswerteparameter!Z$5*Rohdaten!AJ5*Rohdaten!AL5) -> 0 | O3: =(Auswerteparameter!AE$5*Rohdaten!AP5*Rohdaten!AR5) -> 0 | Q3: =(Auswerteparameter!AJ$5*Rohdaten!AU5*Rohdaten!AW5) -> 0 | S3: =(Auswerteparameter!AO$5*Rohdaten!BF5*Rohdaten!BH5) -> 0 | U3: =(Auswerteparameter!AT$5*Rohdaten!BK5*Rohdaten!BM5) -> 0
C4: =(Auswerteparameter!A$5*Rohdaten!K6*Rohdaten!M6) -> -5.6794286e-10 | G4: =(Auswerteparameter!K$5*Rohdaten!U6*Rohdaten!W6) -> -1.3211374e-09 | I4: =(Rohdaten!Z6*Rohdaten!AB6*Auswerteparameter!P$5) -> -2.0942408e-09 | K4: =(Auswerteparameter!U$5*Rohdaten!AE6*Rohdaten!AG6) -> -2.2330097e-07 | M4: =(Auswerteparameter!Z$5*Rohdaten!AJ6*Rohdaten!AL6) -> -1.7793921e-09 | O4: =(Auswerteparameter!AE$5*Rohdaten!AP6*Rohdaten!AR6) -> -8.9020772e-10 | Q4: =(Auswerteparameter!AJ$5*Rohdaten!AU6*Rohdaten!AW6) -> -8.5118457e-10 | S4: =(Auswerteparameter!AO$5*Rohdaten!BF6*Rohdaten!BH6) -> -6.6159221e-07 | U4: =(Auswerteparameter!AT$5*Rohdaten!BK6*Rohdaten!BM6) -> -4.0106952e-09
C5: =(Auswerteparameter!A$5*Rohdaten!K7*Rohdaten!M7) -> -2.2857143e-09 | G5: =(Auswerteparameter!K$5*Rohdaten!U7*Rohdaten!W7) -> -5.6872038e-09 | I5: =(Rohdaten!Z7*Rohdaten!AB7*Auswerteparameter!P$5) -> -2.0942408e-09 | K5: =(Auswerteparameter!U$5*Rohdaten!AE7*Rohdaten!AG7) -> -3.907767e-07 | M5: =(Auswerteparameter!Z$5*Rohdaten!AJ7*Rohdaten!AL7) -> -1.7793921e-09 | O5: =(Auswerteparameter!AE$5*Rohdaten!AP7*Rohdaten!AR7) -> -3.5608309e-09 | Q5: =(Auswerteparameter!AJ$5*Rohdaten!AU7*Rohdaten!AW7) -> -3.4047383e-09 | S5: =(Auswerteparameter!AO$5*Rohdaten!BF7*Rohdaten!BH7) -> -1.3231844e-06 | U5: =(Auswerteparameter!AT$5*Rohdaten!BK7*Rohdaten!BM7) -> -8.0213904e-09
C6: =(Auswerteparameter!A$5*Rohdaten!K8*Rohdaten!M8) -> -1.7142857e-09 | G6: =(Auswerteparameter!K$5*Rohdaten!U8*Rohdaten!W8) -> -4.0935071e-09 | I6: =(Rohdaten!Z8*Rohdaten!AB8*Auswerteparameter!P$5) -> -6.2827225e-09 | K6: =(Auswerteparameter!U$5*Rohdaten!AE8*Rohdaten!AG8) -> -6.6990291e-07 | M6: =(Auswerteparameter!Z$5*Rohdaten!AJ8*Rohdaten!AL8) -> -5.3381764e-09 | O6: =(Auswerteparameter!AE$5*Rohdaten!AP8*Rohdaten!AR8) -> -2.6543323e-09 | Q6: =(Auswerteparameter!AJ$5*Rohdaten!AU8*Rohdaten!AW8) -> -2.5535537e-09 | S6: =(Auswerteparameter!AO$5*Rohdaten!BF8*Rohdaten!BH8) -> -1.9847766e-06 | U6: =(Auswerteparameter!AT$5*Rohdaten!BK8*Rohdaten!BM8) -> -1.2032086e-08
C7: =(Auswerteparameter!A$5*Rohdaten!K9*Rohdaten!M9) -> -4.5714286e-09 | G7: =(Auswerteparameter!K$5*Rohdaten!U9*Rohdaten!W9) -> -1.1374408e-08 | I7: =(Rohdaten!Z9*Rohdaten!AB9*Auswerteparameter!P$5) -> -4.1884817e-09 | K7: =(Auswerteparameter!U$5*Rohdaten!AE9*Rohdaten!AG9) -> -7.815534e-07 | M7: =(Auswerteparameter!Z$5*Rohdaten!AJ9*Rohdaten!AL9) -> -3.0416929e-09 | O7: =(Auswerteparameter!AE$5*Rohdaten!AP9*Rohdaten!AR9) -> -7.1216617e-09 | Q7: =(Auswerteparameter!AJ$5*Rohdaten!AU9*Rohdaten!AW9) -> -6.8094765e-09 | S7: =(Auswerteparameter!AO$5*Rohdaten!BF9*Rohdaten!BH9) -> -2.6463689e-06 | U7: =(Auswerteparameter!AT$5*Rohdaten!BK9*Rohdaten!BM9) -> -1.6042781e-08
C8: =(Auswerteparameter!A$5*Rohdaten!K10*Rohdaten!M10) -> -2.8431429e-09 | G8: =(Auswerteparameter!K$5*Rohdaten!U10*Rohdaten!W10) -> -6.4322275e-09 | I8: =(Rohdaten!Z10*Rohdaten!AB10*Auswerteparameter!P$5) -> -1.0471204e-08 | K8: =(Auswerteparameter!U$5*Rohdaten!AE10*Rohdaten!AG10) -> -1.1165049e-06 | M8: =(Auswerteparameter!Z$5*Rohdaten!AJ10*Rohdaten!AL10) -> -8.8969607e-09 | O8: =(Auswerteparameter!AE$5*Rohdaten!AP10*Rohdaten!AR10) -> -4.4510386e-09 | Q8: =(Auswerteparameter!AJ$5*Rohdaten!AU10*Rohdaten!AW10) -> -4.2559228e-09 | S8: =(Auswerteparameter!AO$5*Rohdaten!BF10*Rohdaten!BH10) -> -3.3079611e-06 | U8: =(Auswerteparameter!AT$5*Rohdaten!BK10*Rohdaten!BM10) -> -2.0053476e-08
C9: =(Auswerteparameter!A$5*Rohdaten!K11*Rohdaten!M11) -> -6.8571429e-09 | G9: =(Auswerteparameter!K$5*Rohdaten!U11*Rohdaten!W11) -> -1.7061611e-08 | I9: =(Rohdaten!Z11*Rohdaten!AB11*Auswerteparameter!P$5) -> -6.2827225e-09 | K9: =(Auswerteparameter!U$5*Rohdaten!AE11*Rohdaten!AG11) -> -1.1723301e-06 | M9: =(Auswerteparameter!Z$5*Rohdaten!AJ11*Rohdaten!AL11) -> -5.3381764e-09 | O9: =(Auswerteparameter!AE$5*Rohdaten!AP11*Rohdaten!AR11) -> -1.0682493e-08 | Q9: =(Auswerteparameter!AJ$5*Rohdaten!AU11*Rohdaten!AW11) -> -1.0214215e-08 | S9: =(Auswerteparameter!AO$5*Rohdaten!BF11*Rohdaten!BH11) -> -3.9695533e-06 | U9: =(Auswerteparameter!AT$5*Rohdaten!BK11*Rohdaten!BM11) -> -2.4064171e-08
C10: =(Auswerteparameter!A$5*Rohdaten!K12*Rohdaten!M12) -> -3.668e-09 | G10: =(Auswerteparameter!K$5*Rohdaten!U12*Rohdaten!W12) -> -9.3932701e-09 | I10: =(Rohdaten!Z12*Rohdaten!AB12*Auswerteparameter!P$5) -> -1.4659686e-08 | K10: =(Auswerteparameter!U$5*Rohdaten!AE12*Rohdaten!AG12) -> -1.5631068e-06 | M10: =(Auswerteparameter!Z$5*Rohdaten!AJ12*Rohdaten!AL12) -> -1.2455745e-08 | O10: =(Auswerteparameter!AE$5*Rohdaten!AP12*Rohdaten!AR12) -> -6.231454e-09 | Q10: =(Auswerteparameter!AJ$5*Rohdaten!AU12*Rohdaten!AW12) -> -5.958292e-09 | S10: =(Auswerteparameter!AO$5*Rohdaten!BF12*Rohdaten!BH12) -> -4.6311455e-06 | U10: =(Auswerteparameter!AT$5*Rohdaten!BK12*Rohdaten!BM12) -> -2.8074866e-08
C11: =(Auswerteparameter!A$5*Rohdaten!K13*Rohdaten!M13) -> -9.1428571e-09 | G11: =(Auswerteparameter!K$5*Rohdaten!U13*Rohdaten!W13) -> -2.2748815e-08 | I11: =(Rohdaten!Z13*Rohdaten!AB13*Auswerteparameter!P$5) -> -8.3769634e-09 | K11: =(Auswerteparameter!U$5*Rohdaten!AE13*Rohdaten!AG13) -> -1.5631068e-06 | M11: =(Auswerteparameter!Z$5*Rohdaten!AJ13*Rohdaten!AL13) -> -5.9275111e-09 | O11: =(Auswerteparameter!AE$5*Rohdaten!AP13*Rohdaten!AR13) -> -1.4243323e-08 | Q11: =(Auswerteparameter!AJ$5*Rohdaten!AU13*Rohdaten!AW13) -> -1.3618953e-08 | S11: =(Auswerteparameter!AO$5*Rohdaten!BF13*Rohdaten!BH13) -> -5.2927377e-06 | U11: =(Auswerteparameter!AT$5*Rohdaten!BK13*Rohdaten!BM13) -> -3.2085561e-08
C12: =(Auswerteparameter!A$5*Rohdaten!K14*Rohdaten!M14) -> -5.0045143e-09 | G12: =(Auswerteparameter!K$5*Rohdaten!U14*Rohdaten!W14) -> -8.703981e-09 | I12: =(Rohdaten!Z14*Rohdaten!AB14*Auswerteparameter!P$5) -> -1.8848168e-08 | K12: =(Auswerteparameter!U$5*Rohdaten!AE14*Rohdaten!AG14) -> -2.0097087e-06 | M12: =(Auswerteparameter!Z$5*Rohdaten!AJ14*Rohdaten!AL14) -> -8.0072646e-09 | O12: =(Auswerteparameter!AE$5*Rohdaten!AP14*Rohdaten!AR14) -> -8.0118694e-09 | Q12: =(Auswerteparameter!AJ$5*Rohdaten!AU14*Rohdaten!AW14) -> -7.6606611e-09 | S12: =(Auswerteparameter!AO$5*Rohdaten!BF14*Rohdaten!BH14) -> -5.9543299e-06 | U12: =(Auswerteparameter!AT$5*Rohdaten!BK14*Rohdaten!BM14) -> -3.6096257e-08
C13: =(Auswerteparameter!A$5*Rohdaten!K15*Rohdaten!M15) -> -1.1428571e-08 | G13: =(Auswerteparameter!K$5*Rohdaten!U15*Rohdaten!W15) -> -2.8436019e-08 | I13: =(Rohdaten!Z15*Rohdaten!AB15*Auswerteparameter!P$5) -> -1.0471204e-08 | K13: =(Auswerteparameter!U$5*Rohdaten!AE15*Rohdaten!AG15) -> -1.9538835e-06 | M13: =(Auswerteparameter!Z$5*Rohdaten!AJ15*Rohdaten!AL15) -> -8.8969607e-09 | O13: =(Auswerteparameter!AE$5*Rohdaten!AP15*Rohdaten!AR15) -> -1.7804154e-08 | Q13: =(Auswerteparameter!AJ$5*Rohdaten!AU15*Rohdaten!AW15) -> -1.7023691e-08 | S13: =(Auswerteparameter!AO$5*Rohdaten!BF15*Rohdaten!BH15) -> -6.6159221e-06 | U13: =(Auswerteparameter!AT$5*Rohdaten!BK15*Rohdaten!BM15) -> -4.0106952e-08
C14: =(Auswerteparameter!A$5*Rohdaten!K16*Rohdaten!M16) -> -5.8098857e-09 | G14: =(Auswerteparameter!K$5*Rohdaten!U16*Rohdaten!W16) -> -1.563981e-08 | I14: =(Rohdaten!Z16*Rohdaten!AB16*Auswerteparameter!P$5) -> -2.3036649e-08 | K14: =(Auswerteparameter!U$5*Rohdaten!AE16*Rohdaten!AG16) -> -2.4563107e-06 | M14: =(Auswerteparameter!Z$5*Rohdaten!AJ16*Rohdaten!AL16) -> -1.9573314e-08 | O14: =(Auswerteparameter!AE$5*Rohdaten!AP16*Rohdaten!AR16) -> -9.7922849e-09 | Q14: =(Auswerteparameter!AJ$5*Rohdaten!AU16*Rohdaten!AW16) -> -9.3630302e-09 | S14: =(Auswerteparameter!AO$5*Rohdaten!BF16*Rohdaten!BH16) -> -7.2775143e-06 | U14: =(Auswerteparameter!AT$5*Rohdaten!BK16*Rohdaten!BM16) -> -4.4117647e-08
... C1352: =(Auswerteparameter!A$5*Rohdaten!K1354*Rohdaten!M1354) -> -0.00075235657 | G1352: =(Auswerteparameter!K$5*Rohdaten!U1354*Rohdaten!W1354) -> 0.0023303815 | I1352: =(Rohdaten!Z1354*Rohdaten!AB1354*Auswerteparameter!P$5) -> -4.2376963e-06 | K1352: =(Auswerteparameter!U$5*Rohdaten!AE1354*Rohdaten!AG1354) -> -0.0021462852 | M1352: =(Auswerteparameter!Z$5*Rohdaten!AJ1354*Rohdaten!AL1354) -> -2.4004e-06 | O1352: =(Auswerteparameter!AE$5*Rohdaten!AP1354*Rohdaten!AR1354) -> -0.0011168279 | Q1352: =(Auswerteparameter!AJ$5*Rohdaten!AU1354*Rohdaten!AW1354) -> -0.0010242372 | S1352: =(Auswerteparameter!AO$5*Rohdaten!BF1354*Rohdaten!BH1354) -> -0.077727582 | U1352: =(Auswerteparameter!AT$5*Rohdaten!BK1354*Rohdaten!BM1354) -> -8.1156417e-06
C1353: =(Auswerteparameter!A$5*Rohdaten!K1355*Rohdaten!M1355) -> -0.00075368571 | G1353: =(Auswerteparameter!K$5*Rohdaten!U1355*Rohdaten!W1355) -> 0.0023359479 | I1353: =(Rohdaten!Z1355*Rohdaten!AB1355*Auswerteparameter!P$5) -> -5.6544503e-06 | K1353: =(Auswerteparameter!U$5*Rohdaten!AE1355*Rohdaten!AG1355) -> -0.0021855583 | O1353: =(Auswerteparameter!AE$5*Rohdaten!AP1355*Rohdaten!AR1355) -> -0.0011188576 | Q1353: =(Auswerteparameter!AJ$5*Rohdaten!AU1355*Rohdaten!AW1355) -> -0.0010249965 | S1353: =(Auswerteparameter!AO$5*Rohdaten!BF1355*Rohdaten!BH1355) -> -0.077704005 | U1353: =(Auswerteparameter!AT$5*Rohdaten!BK1355*Rohdaten!BM1355) -> -5.4144385e-06
C1354: =(Auswerteparameter!A$5*Rohdaten!K1356*Rohdaten!M1356) -> -0.000753472 | G1354: =(Auswerteparameter!K$5*Rohdaten!U1356*Rohdaten!W1356) -> 0.0023357573 | I1354: =(Rohdaten!Z1356*Rohdaten!AB1356*Auswerteparameter!P$5) -> -4.2439791e-06 | K1354: =(Auswerteparameter!U$5*Rohdaten!AE1356*Rohdaten!AG1356) -> -0.0021494672 | O1354: =(Auswerteparameter!AE$5*Rohdaten!AP1356*Rohdaten!AR1356) -> -0.0011184837 | Q1354: =(Auswerteparameter!AJ$5*Rohdaten!AU1356*Rohdaten!AW1356) -> -0.0010257557 | S1354: =(Auswerteparameter!AO$5*Rohdaten!BF1356*Rohdaten!BH1356) -> -0.077924075 | U1354: =(Auswerteparameter!AT$5*Rohdaten!BK1356*Rohdaten!BM1356) -> -8.1276738e-06
C1355: =(Auswerteparameter!A$5*Rohdaten!K1357*Rohdaten!M1357) -> -0.00075480229 | G1355: =(Auswerteparameter!K$5*Rohdaten!U1357*Rohdaten!W1357) -> 0.0023413308 | I1355: =(Rohdaten!Z1357*Rohdaten!AB1357*Auswerteparameter!P$5) -> -5.6628272e-06 | K1355: =(Auswerteparameter!U$5*Rohdaten!AE1357*Rohdaten!AG1357) -> -0.0021887961 | O1355: =(Auswerteparameter!AE$5*Rohdaten!AP1357*Rohdaten!AR1357) -> -0.0011193116 | Q1355: =(Auswerteparameter!AJ$5*Rohdaten!AU1357*Rohdaten!AW1357) -> -0.001026515 | S1355: =(Auswerteparameter!AO$5*Rohdaten!BF1357*Rohdaten!BH1357) -> -0.077819123 | U1355: =(Auswerteparameter!AT$5*Rohdaten!BK1357*Rohdaten!BM1357) -> -5.4224599e-06
C1356: =(Auswerteparameter!A$5*Rohdaten!K1358*Rohdaten!M1358) -> -0.00075458743 | G1356: =(Auswerteparameter!K$5*Rohdaten!U1358*Rohdaten!W1358) -> 0.0023411389 | I1356: =(Rohdaten!Z1358*Rohdaten!AB1358*Auswerteparameter!P$5) -> -4.2502618e-06 | K1356: =(Auswerteparameter!U$5*Rohdaten!AE1358*Rohdaten!AG1358) -> -0.0021526493 | O1356: =(Auswerteparameter!AE$5*Rohdaten!AP1358*Rohdaten!AR1358) -> -0.0011201395 | Q1356: =(Auswerteparameter!AJ$5*Rohdaten!AU1358*Rohdaten!AW1358) -> -0.0010284259 | S1356: =(Auswerteparameter!AO$5*Rohdaten!BF1358*Rohdaten!BH1358) -> -0.078039433 | U1356: =(Auswerteparameter!AT$5*Rohdaten!BK1358*Rohdaten!BM1358) -> -8.1397059e-06
C1357: =(Auswerteparameter!A$5*Rohdaten!K1359*Rohdaten!M1359) -> -0.00075591886 | G1357: =(Auswerteparameter!K$5*Rohdaten!U1359*Rohdaten!W1359) -> 0.0023447943 | I1357: =(Rohdaten!Z1359*Rohdaten!AB1359*Auswerteparameter!P$5) -> -5.6712042e-06 | K1357: =(Auswerteparameter!U$5*Rohdaten!AE1359*Rohdaten!AG1359) -> -0.002192034 | O1357: =(Auswerteparameter!AE$5*Rohdaten!AP1359*Rohdaten!AR1359) -> -0.0011209674 | Q1357: =(Auswerteparameter!AJ$5*Rohdaten!AU1359*Rohdaten!AW1359) -> -0.0010280335 | S1357: =(Auswerteparameter!AO$5*Rohdaten!BF1359*Rohdaten!BH1359) -> -0.07793424 | U1357: =(Auswerteparameter!AT$5*Rohdaten!BK1359*Rohdaten!BM1359) -> -5.4304813e-06
C1358: =(Auswerteparameter!A$5*Rohdaten!K1360*Rohdaten!M1360) -> -0.00075570286 | G1358: =(Auswerteparameter!K$5*Rohdaten!U1360*Rohdaten!W1360) -> 0.0023465261 | I1358: =(Rohdaten!Z1360*Rohdaten!AB1360*Auswerteparameter!P$5) -> -4.2565445e-06 | K1358: =(Auswerteparameter!U$5*Rohdaten!AE1360*Rohdaten!AG1360) -> -0.0021558313 | O1358: =(Auswerteparameter!AE$5*Rohdaten!AP1360*Rohdaten!AR1360) -> -0.0011217953 | Q1358: =(Auswerteparameter!AJ$5*Rohdaten!AU1360*Rohdaten!AW1360) -> -0.0010299461 | S1358: =(Auswerteparameter!AO$5*Rohdaten!BF1360*Rohdaten!BH1360) -> -0.078073294 | U1358: =(Auswerteparameter!AT$5*Rohdaten!BK1360*Rohdaten!BM1360) -> -8.151738e-06
C1359: =(Auswerteparameter!A$5*Rohdaten!K1361*Rohdaten!M1361) -> -0.00075703543 | G1359: =(Auswerteparameter!K$5*Rohdaten!U1361*Rohdaten!W1361) -> 0.0023501858 | I1359: =(Rohdaten!Z1361*Rohdaten!AB1361*Auswerteparameter!P$5) -> -5.6795812e-06 | K1359: =(Auswerteparameter!U$5*Rohdaten!AE1361*Rohdaten!AG1361) -> -0.0021574223 | O1359: =(Auswerteparameter!AE$5*Rohdaten!AP1361*Rohdaten!AR1361) -> -0.0011238303 | Q1359: =(Auswerteparameter!AJ$5*Rohdaten!AU1361*Rohdaten!AW1361) -> -0.001029552 | S1359: =(Auswerteparameter!AO$5*Rohdaten!BF1361*Rohdaten!BH1361) -> -0.078130913 | U1359: =(Auswerteparameter!AT$5*Rohdaten!BK1361*Rohdaten!BM1361) -> -8.157754e-06
C1360: =(Auswerteparameter!A$5*Rohdaten!K1362*Rohdaten!M1362) -> -0.00075681829 | G1360: =(Auswerteparameter!K$5*Rohdaten!U1362*Rohdaten!W1362) -> 0.002351919 | I1360: =(Rohdaten!Z1362*Rohdaten!AB1362*Auswerteparameter!P$5) -> -4.2628272e-06 | K1360: =(Auswerteparameter!U$5*Rohdaten!AE1362*Rohdaten!AG1362) -> -0.0021590133 | O1360: =(Auswerteparameter!AE$5*Rohdaten!AP1362*Rohdaten!AR1362) -> -0.0011246591 | Q1360: =(Auswerteparameter!AJ$5*Rohdaten!AU1362*Rohdaten!AW1362) -> -0.0010314663 | S1360: =(Auswerteparameter!AO$5*Rohdaten!BF1362*Rohdaten!BH1362) -> -0.078270148 | U1360: =(Auswerteparameter!AT$5*Rohdaten!BK1362*Rohdaten!BM1362) -> -8.1637701e-06
C1361: =(Auswerteparameter!A$5*Rohdaten!K1363*Rohdaten!M1363) -> -0.000758152 | G1361: =(Auswerteparameter!K$5*Rohdaten!U1363*Rohdaten!W1363) -> 0.0023575137 | I1361: =(Rohdaten!Z1363*Rohdaten!AB1363*Auswerteparameter!P$5) -> -7.1099476e-06 | K1361: =(Auswerteparameter!U$5*Rohdaten!AE1363*Rohdaten!AG1363) -> -0.0021606044 | O1361: =(Auswerteparameter!AE$5*Rohdaten!AP1363*Rohdaten!AR1363) -> -0.0011254878 | Q1361: =(Auswerteparameter!AJ$5*Rohdaten!AU1363*Rohdaten!AW1363) -> -0.0010322264 | S1361: =(Auswerteparameter!AO$5*Rohdaten!BF1363*Rohdaten!BH1363) -> -0.07824615 | U1361: =(Auswerteparameter!AT$5*Rohdaten!BK1363*Rohdaten!BM1363) -> -8.1697861e-06
C1362: =(Auswerteparameter!A$5*Rohdaten!K1364*Rohdaten!M1364) -> -0.00075793371 | G1362: =(Auswerteparameter!K$5*Rohdaten!U1364*Rohdaten!W1364) -> 0.0023573175 | I1362: =(Rohdaten!Z1364*Rohdaten!AB1364*Auswerteparameter!P$5) -> -4.2691099e-06 | K1362: =(Auswerteparameter!U$5*Rohdaten!AE1364*Rohdaten!AG1364) -> -0.0021242621 | O1362: =(Auswerteparameter!AE$5*Rohdaten!AP1364*Rohdaten!AR1364) -> -0.0011263166 | Q1362: =(Auswerteparameter!AJ$5*Rohdaten!AU1364*Rohdaten!AW1364) -> -0.0010329865 | S1362: =(Auswerteparameter!AO$5*Rohdaten!BF1364*Rohdaten!BH1364) -> -0.078303769 | U1362: =(Auswerteparameter!AT$5*Rohdaten!BK1364*Rohdaten!BM1364) -> -8.1758021e-06
C1363: =(Auswerteparameter!A$5*Rohdaten!K1365*Rohdaten!M1365) -> -0.00075926857 | G1363: =(Auswerteparameter!K$5*Rohdaten!U1365*Rohdaten!W1365) -> 0.0023629194 | I1363: =(Rohdaten!Z1365*Rohdaten!AB1365*Auswerteparameter!P$5) -> -5.6963351e-06 | K1363: =(Auswerteparameter!U$5*Rohdaten!AE1365*Rohdaten!AG1365) -> -0.0021637864 | O1363: =(Auswerteparameter!AE$5*Rohdaten!AP1365*Rohdaten!AR1365) -> -0.0011271454 | Q1363: =(Auswerteparameter!AJ$5*Rohdaten!AU1365*Rohdaten!AW1365) -> -0.001032589 | S1363: =(Auswerteparameter!AO$5*Rohdaten!BF1365*Rohdaten!BH1365) -> -0.078279591 | U1363: =(Auswerteparameter!AT$5*Rohdaten!BK1365*Rohdaten!BM1365) -> -8.1818182e-06
C1364: =(Auswerteparameter!A$5*Rohdaten!K1366*Rohdaten!M1366) -> -0.00075904914 | G1364: =(Auswerteparameter!K$5*Rohdaten!U1366*Rohdaten!W1366) -> 0.0023627218 | I1364: =(Rohdaten!Z1366*Rohdaten!AB1366*Auswerteparameter!P$5) -> -4.2753927e-06 | K1364: =(Auswerteparameter!U$5*Rohdaten!AE1366*Rohdaten!AG1366) -> -0.0021653774 | O1364: =(Auswerteparameter!AE$5*Rohdaten!AP1366*Rohdaten!AR1366) -> -0.0011279742 | Q1364: =(Auswerteparameter!AJ$5*Rohdaten!AU1366*Rohdaten!AW1366) -> -0.0010345067 | S1364: =(Auswerteparameter!AO$5*Rohdaten!BF1366*Rohdaten!BH1366) -> -0.078419006 | U1364: =(Auswerteparameter!AT$5*Rohdaten!BK1366*Rohdaten!BM1366) -> -8.1878342e-06
... C1499: =(Auswerteparameter!A$5*Rohdaten!K1501*Rohdaten!M1501) -> -0.000843744 | G1499: =(Auswerteparameter!K$5*Rohdaten!U1501*Rohdaten!W1501) -> 0.0026608948 | I1499: =(Rohdaten!Z1501*Rohdaten!AB1501*Auswerteparameter!P$5) -> -6.2659686e-06 | K1499: =(Auswerteparameter!U$5*Rohdaten!AE1501*Rohdaten!AG1501) -> -0.0022131359 | O1499: =(Auswerteparameter!AE$5*Rohdaten!AP1501*Rohdaten!AR1501) -> -0.0012558409 | Q1499: =(Auswerteparameter!AJ$5*Rohdaten!AU1501*Rohdaten!AW1501) -> -0.0011676822 | S1499: =(Auswerteparameter!AO$5*Rohdaten!BF1501*Rohdaten!BH1501) -> -0.085387737 | U1499: =(Auswerteparameter!AT$5*Rohdaten!BK1501*Rohdaten!BM1501) -> -1.5e-05
C1500: =(Auswerteparameter!A$5*Rohdaten!K1502*Rohdaten!M1502) -> -0.00084345257 | G1500: =(Auswerteparameter!K$5*Rohdaten!U1502*Rohdaten!W1502) -> 0.002660545 | I1500: =(Rohdaten!Z1502*Rohdaten!AB1502*Auswerteparameter!P$5) -> -4.7026178e-06 | K1500: =(Auswerteparameter!U$5*Rohdaten!AE1502*Rohdaten!AG1502) -> -0.0022146153 | O1500: =(Auswerteparameter!AE$5*Rohdaten!AP1502*Rohdaten!AR1502) -> -0.0012566804 | Q1500: =(Auswerteparameter!AJ$5*Rohdaten!AU1502*Rohdaten!AW1502) -> -0.001169737 | S1500: =(Auswerteparameter!AO$5*Rohdaten!BF1502*Rohdaten!BH1502) -> -0.085534852
C1501: =(Auswerteparameter!A$5*Rohdaten!K1503*Rohdaten!M1503) -> -0.000844872 | G1501: =(Auswerteparameter!K$5*Rohdaten!U1503*Rohdaten!W1503) -> 0.0026644521 | I1501: =(Rohdaten!Z1503*Rohdaten!AB1503*Auswerteparameter!P$5) -> -6.2743455e-06 | K1501: =(Auswerteparameter!U$5*Rohdaten!AE1503*Rohdaten!AG1503) -> -0.0022579078 | O1501: =(Auswerteparameter!AE$5*Rohdaten!AP1503*Rohdaten!AR1503) -> -0.0012588534 | Q1501: =(Auswerteparameter!AJ$5*Rohdaten!AU1503*Rohdaten!AW1503) -> -0.0011705184 | S1501: =(Auswerteparameter!AO$5*Rohdaten!BF1503*Rohdaten!BH1503) -> -0.085501892
C1502: =(Auswerteparameter!A$5*Rohdaten!K1504*Rohdaten!M1504) -> -0.00084457943 | G1502: =(Auswerteparameter!K$5*Rohdaten!U1504*Rohdaten!W1504) -> 0.0026662308 | I1502: =(Rohdaten!Z1504*Rohdaten!AB1504*Auswerteparameter!P$5) -> -4.7089005e-06 | K1502: =(Auswerteparameter!U$5*Rohdaten!AE1504*Rohdaten!AG1504) -> -0.002217574 | O1502: =(Auswerteparameter!AE$5*Rohdaten!AP1504*Rohdaten!AR1504) -> -0.0012596938 | Q1502: =(Auswerteparameter!AJ$5*Rohdaten!AU1504*Rohdaten!AW1504) -> -0.0011712998 | S1502: =(Auswerteparameter!AO$5*Rohdaten!BF1504*Rohdaten!BH1504) -> -0.08555897
C1503: =(Auswerteparameter!A$5*Rohdaten!K1505*Rohdaten!M1505) -> -0.000846 | G1503: =(Auswerteparameter!K$5*Rohdaten!U1505*Rohdaten!W1505) -> 0.0026680095 | I1503: =(Rohdaten!Z1505*Rohdaten!AB1505*Auswerteparameter!P$5) -> -7.8534031e-06 | K1503: =(Auswerteparameter!U$5*Rohdaten!AE1505*Rohdaten!AG1505) -> -0.0022609223 | O1503: =(Auswerteparameter!AE$5*Rohdaten!AP1505*Rohdaten!AR1505) -> -0.0012605341 | Q1503: =(Auswerteparameter!AJ$5*Rohdaten!AU1505*Rohdaten!AW1505) -> -0.0011720811 | S1503: =(Auswerteparameter!AO$5*Rohdaten!BF1505*Rohdaten!BH1505) -> -0.08552583
C1504: =(Auswerteparameter!A$5*Rohdaten!K1506*Rohdaten!M1506) -> -0.00084570629 | G1504: =(Auswerteparameter!K$5*Rohdaten!U1506*Rohdaten!W1506) -> 0.0026697882 | I1504: =(Rohdaten!Z1506*Rohdaten!AB1506*Auswerteparameter!P$5) -> -4.7151832e-06 | K1504: =(Auswerteparameter!U$5*Rohdaten!AE1506*Rohdaten!AG1506) -> -0.0022205328 | O1504: =(Auswerteparameter!AE$5*Rohdaten!AP1506*Rohdaten!AR1506) -> -0.0012613745 | Q1504: =(Auswerteparameter!AJ$5*Rohdaten!AU1506*Rohdaten!AW1506) -> -0.0011741402 | S1504: =(Auswerteparameter!AO$5*Rohdaten!BF1506*Rohdaten!BH1506) -> -0.085673124
C1505: =(Auswerteparameter!A$5*Rohdaten!K1507*Rohdaten!M1507) -> -0.000847128 | G1505: =(Auswerteparameter!K$5*Rohdaten!U1507*Rohdaten!W1507) -> 0.0026715668 | I1505: =(Rohdaten!Z1507*Rohdaten!AB1507*Auswerteparameter!P$5) -> -6.2910995e-06 | K1505: =(Auswerteparameter!U$5*Rohdaten!AE1507*Rohdaten!AG1507) -> -0.0022639369 | O1505: =(Auswerteparameter!AE$5*Rohdaten!AP1507*Rohdaten!AR1507) -> -0.0012622148 | Q1505: =(Auswerteparameter!AJ$5*Rohdaten!AU1507*Rohdaten!AW1507) -> -0.0011736439 | S1505: =(Auswerteparameter!AO$5*Rohdaten!BF1507*Rohdaten!BH1507) -> -0.085639864
C1506: =(Auswerteparameter!A$5*Rohdaten!K1508*Rohdaten!M1508) -> -0.00084683314 | G1506: =(Auswerteparameter!K$5*Rohdaten!U1508*Rohdaten!W1508) -> 0.0026754825 | I1506: =(Rohdaten!Z1508*Rohdaten!AB1508*Auswerteparameter!P$5) -> -4.721466e-06 | K1506: =(Auswerteparameter!U$5*Rohdaten!AE1508*Rohdaten!AG1508) -> -0.0022234915 | O1506: =(Auswerteparameter!AE$5*Rohdaten!AP1508*Rohdaten!AR1508) -> -0.0012630552 | Q1506: =(Auswerteparameter!AJ$5*Rohdaten!AU1508*Rohdaten!AW1508) -> -0.0011757046 | S1506: =(Auswerteparameter!AO$5*Rohdaten!BF1508*Rohdaten!BH1508) -> -0.085787279
C1507: =(Auswerteparameter!A$5*Rohdaten!K1509*Rohdaten!M1509) -> -0.000848256 | G1507: =(Auswerteparameter!K$5*Rohdaten!U1509*Rohdaten!W1509) -> 0.0026772626 | I1507: =(Rohdaten!Z1509*Rohdaten!AB1509*Auswerteparameter!P$5) -> -6.2994764e-06 | K1507: =(Auswerteparameter!U$5*Rohdaten!AE1509*Rohdaten!AG1509) -> -0.0022249709 | O1507: =(Auswerteparameter!AE$5*Rohdaten!AP1509*Rohdaten!AR1509) -> -0.0012638955 | Q1507: =(Auswerteparameter!AJ$5*Rohdaten!AU1509*Rohdaten!AW1509) -> -0.0011764869 | S1507: =(Auswerteparameter!AO$5*Rohdaten!BF1509*Rohdaten!BH1509) -> -0.085663441
C1508: =(Auswerteparameter!A$5*Rohdaten!K1510*Rohdaten!M1510) -> -0.00084796 | G1508: =(Auswerteparameter!K$5*Rohdaten!U1510*Rohdaten!W1510) -> 0.0026790427 | I1508: =(Rohdaten!Z1510*Rohdaten!AB1510*Auswerteparameter!P$5) -> -4.7277487e-06 | K1508: =(Auswerteparameter!U$5*Rohdaten!AE1510*Rohdaten!AG1510) -> -0.0022264502 | O1508: =(Auswerteparameter!AE$5*Rohdaten!AP1510*Rohdaten!AR1510) -> -0.0012647359 | Q1508: =(Auswerteparameter!AJ$5*Rohdaten!AU1510*Rohdaten!AW1510) -> -0.0011772691 | S1508: =(Auswerteparameter!AO$5*Rohdaten!BF1510*Rohdaten!BH1510) -> -0.085901434
C1509: =(Auswerteparameter!A$5*Rohdaten!K1511*Rohdaten!M1511) -> -0.000849384 | G1509: =(Auswerteparameter!K$5*Rohdaten!U1511*Rohdaten!W1511) -> 0.0026808227 | I1509: =(Rohdaten!Z1511*Rohdaten!AB1511*Auswerteparameter!P$5) -> -6.3078534e-06 | K1509: =(Auswerteparameter!U$5*Rohdaten!AE1511*Rohdaten!AG1511) -> -0.0022279296 | O1509: =(Auswerteparameter!AE$5*Rohdaten!AP1511*Rohdaten!AR1511) -> -0.0012655763 | Q1509: =(Auswerteparameter!AJ$5*Rohdaten!AU1511*Rohdaten!AW1511) -> -0.0011780514 | S1509: =(Auswerteparameter!AO$5*Rohdaten!BF1511*Rohdaten!BH1511) -> -0.085777355
C1510: =(Auswerteparameter!A$5*Rohdaten!K1512*Rohdaten!M1512) -> -0.00084908686 | G1510: =(Auswerteparameter!K$5*Rohdaten!U1512*Rohdaten!W1512) -> 0.0026826028 | I1510: =(Rohdaten!Z1512*Rohdaten!AB1512*Auswerteparameter!P$5) -> -4.7340314e-06 | K1510: =(Auswerteparameter!U$5*Rohdaten!AE1512*Rohdaten!AG1512) -> -0.002229409 | O1510: =(Auswerteparameter!AE$5*Rohdaten!AP1512*Rohdaten!AR1512) -> -0.0012677582 | Q1510: =(Auswerteparameter!AJ$5*Rohdaten!AU1512*Rohdaten!AW1512) -> -0.0011801163 | S1510: =(Auswerteparameter!AO$5*Rohdaten!BF1512*Rohdaten!BH1512) -> -0.08592495
C1511: =(Auswerteparameter!A$5*Rohdaten!K1513*Rohdaten!M1513) -> -0.000850512 | G1511: =(Auswerteparameter!K$5*Rohdaten!U1513*Rohdaten!W1513) -> 0.0026843829 | I1511: =(Rohdaten!Z1513*Rohdaten!AB1513*Auswerteparameter!P$5) -> -6.3162304e-06 | K1511: =(Auswerteparameter!U$5*Rohdaten!AE1513*Rohdaten!AG1513) -> -0.0022308883 | O1511: =(Auswerteparameter!AE$5*Rohdaten!AP1513*Rohdaten!AR1513) -> -0.0012685994 | Q1511: =(Auswerteparameter!AJ$5*Rohdaten!AU1513*Rohdaten!AW1513) -> -0.0011796158 | S1511: =(Auswerteparameter!AO$5*Rohdaten!BF1513*Rohdaten!BH1513) -> -0.085800571
...

Sheet MinMax
B1: #4 | D1: #5 | F1: #6 | H1: #7 | J1: #8 | L1: #9 | N1: #10 | P1: #11 | R1: #13 | T1: #14
A2: MIN | B2: =MIN(Rohdaten!M5:M3421) -> -0.988 | D2: =MIN(Rohdaten!R5:R10000) -> -0.008 | F2: =MIN(Rohdaten!W5:W10000) -> -0.009 | H2: =MIN(Rohdaten!AB6:AB10000) -> -0.005 | J2: =MIN(Rohdaten!AG5:AG10000) -> -0.079 | L2: =MIN(Rohdaten!AL5:AL100000) -> -0.004 | N2: =MIN(Rohdaten!AR5:AR10000) -> -0.951 | P2: =MIN(Rohdaten!AW5:AW10000) -> -0.954 | R2: =MIN(Rohdaten!BH5:BH10000) -> -0.962 | T2: =MIN(Rohdaten!BM5:BM10000) -> -0.005
A4: MAX | B4: =MAX(Rohdaten!M5:M3421) -> -0.0007913 | D4: nicht | F4: =MAX(Rohdaten!W5:W10000) -> 1.259 | H4: =MAX(Rohdaten!AB6:AB10000) -> -0.0009927 | J4: =MAX(Rohdaten!AG5:AG10000) -> -0.006 | L4: =MAX(Rohdaten!AL5:AL100000) -> -0.0007754 | N4: =MAX(Rohdaten!AR5:AR10000) -> -0.0009939 | P4: =MAX(Rohdaten!AW5:AW10000) -> -0.001 | R4: =MAX(Rohdaten!BH5:BH10000) -> -0.01 | T4: =MAX(Rohdaten!BM5:BM10000) -> 0.869
D5: nötig
A6: MIN+MAX | B6: =(B2+B4)*0.5 -> -0.49439565 | F6: =((F2+F4)*0.5) -> 0.625 | H6: =(H2+H4)*0.5 -> -0.00299635 | J6: =(J2+J4)*0.5 -> -0.0425 | L6: =(L2+L4)*0.5 -> -0.0023877 | N6: =(N2+N4)*0.5 -> -0.47599695 | P6: =(P2+P4)*0.5 -> -0.4775 | R6: =(R2+R4)*0.5 -> -0.486 | T6: =(T2+T4)*0.5 -> 0.432

Sheet Windungen etc
C1: RK1 #4 | E1: RK1 #5 | G1: RK1 #6 | I1: RK4 #8 | K1: RK4 #9 | M1: RK3 #10 | O1: RK3 #11 | Q1: RK #13 | S1: RK2 #14
A2: N1 | C2: 605 | E2: 605 | G2: 605 | I2: 1010 | K2: 1010 | M2: 1010 | O2: 1010 | Q2: 1010 | S2: 610
A3: N2 | C3: 80 | E3: 80 | G3: 80 | I3: 250 | K3: 250 | M3: 53 | O3: 53 | Q3: 53 | S3: 56
A4: d_außen | C4: 0.26 | E4: 0.26 | G4: 0.26 | I4: 0.26 | K4: 0.26 | M4: 0.26 | O4: 0.26 | Q4: 0.26 | S4: 0.26
A5: d_innen | C5: 0.22 | E5: 0.22 | G5: 0.22 | I5: 0.22 | K5: 0.22 | M5: 0.22 | O5: 0.22 | Q5: 0.22 | S5: 0.22
A6: Füllfaktor | C6: 0.9 | E6: 0.9 | G6: 0.9 | I6: 1 | K6: 1 | M6: 1 | O6: 1 | Q6: 1 | S6: 0.9
A7: Messb. Flux/ Vs | C7: 0.1 | E7: 0.1 | G7: 0.1 | I7: 0.002 | K7: 0.1 | M7: 0.1 | O7: 0.1 | Q7: 0.1 | S7: 0.1
A8: Messwiederst. /Ohm | C8: 66.7 | E8: 66.7 | G8: 0.2 | I8: 66.7 | K8: 66.7 | M8: 0.2 | O8: 0.2 | Q8: 0.2 | S8: 66.7
A9: Höhe | C9: 0.03 | E9: 0.03 | G9: 0.03 | I9: 0.03 | K9: 0.03 | M9: 0.03 | O9: 0.03 | Q9: 0.03 | S9: 0.03
A10: H/ U_A | C10: =C2/(PI()*0.5*(C4+C5)*C8) -> 12.030078 | E10: =E2/(PI()*0.5*(E4+E5)*E8) -> 12.030078 | G10: =G2/(PI()*0.5*(G4+G5)*G8) -> 4012.0309 | I10: =I2/(PI()*0.5*(I4+I5)*I8) -> 20.08327 | K10: =K2/(PI()*0.5*(K4+K5)*K8) -> 20.08327 | M10: =M2/(PI()*0.5*(M4+M5)*M8) -> 6697.7705 | O10: =O2/(PI()*0.5*(O4+O5)*O8) -> 6697.7705 | Q10: =Q2/(PI()*0.5*(Q4+Q5)*Q8) -> 6697.7705 | S10: =S2/(PI()*0.5*(S4+S5)*S8) -> 12.1295
A11: B/U_B | C11: =2*C7/(C3*C6*(C4-C5)*C9) -> 2.3148148 | E11: =2*E7/(E3*E6*(E4-E5)*E9) -> 2.3148148 | G11: =2*G7/(G3*G6*(G4-G5)*G9) -> 2.3148148 | I11: =2*I7/(I3*I6*(I4-I5)*I9) -> 0.013333333 | K11: =2*K7/(K3*K6*(K4-K5)*K9) -> 0.66666667 | M11: =2*M7/(M3*M6*(M4-M5)*M9) -> 3.1446541 | O11: =2*O7/(O3*O6*(O4-O5)*O9) -> 3.1446541 | Q11: =2*Q7/(Q3*Q6*(Q4-Q5)*Q9) -> 3.1446541 | S11: =2*S7/(S3*S6*(S4-S5)*S9) -> 3.3068783
